2025-06-04 16:05:48,148 - __main__ - INFO - 📁 Found 16 asset files

2025-06-04 16:05:48,148 - __main__ - INFO - ✅ All required assets found

2025-06-04 16:05:48,148 - __main__ - INFO - 🔄 Registering commands with Discord...

/app/main.py:258: DeprecationWarning: datetime.datetime.utcnow() is deprecated and scheduled for removal in a future version. Use timezone-aware objects to represent datetimes in UTC: datetime.datetime.now(datetime.UTC).

  if datetime.utcnow() < cooldown_until:

/app/main.py:259: DeprecationWarning: datetime.datetime.utcnow() is deprecated and scheduled for removal in a future version. Use timezone-aware objects to represent datetimes in UTC: datetime.datetime.now(datetime.UTC).

  remaining = (cooldown_until - datetime.utcnow()).total_seconds()

2025-06-04 16:05:48,148 - __main__ - INFO - ⏰ Global sync in cooldown for 20960s - attempting guild-specific sync...

2025-06-04 16:05:48,148 - __main__ - INFO - 🔧 Attempting guild-specific sync for Emerald Servers...

2025-06-04 16:05:48,763 - __main__ - INFO - Using py-cord 2.6.1 compatible guild sync...

2025-06-04 16:05:48,917 - __main__ - INFO - ✅ Guild commands synced via HTTP: 30 commands in Emerald Servers

2025-06-04 16:05:48,917 - __main__ - INFO - ✅ Commands available via guild-specific sync

2025-06-04 16:05:48,917 - __main__ - INFO - 🎉 Bot setup completed successfully!

Ignoring exception in command online:

Traceback (most recent call last):

  File "/opt/venv/lib/python3.12/site-packages/discord/commands/core.py", line 138, in wrapped

    ret = await coro(arg)

          ^^^^^^^^^^^^^^^

  File "/opt/venv/lib/python3.12/site-packages/discord/commands/core.py", line 1078, in _invoke

    await self.callback(self.cog, ctx, **kwargs)

  File "/app/bot/cogs/stats.py", line 951, in online

    await ctx.defer()

  File "/opt/venv/lib/python3.12/site-packages/discord/interactions.py", line 759, in defer

    raise InteractionResponded(self._parent)

discord.errors.InteractionResponded: This interaction has already been responded to before

 

The above exception was the direct cause of the following exception:

 

Traceback (most recent call last):

  File "/opt/venv/lib/python3.12/site-packages/discord/bot.py", line 1137, in invoke_application_command

    await ctx.command.invoke(ctx)

  File "/opt/venv/lib/python3.12/site-packages/discord/commands/core.py", line 435, in invoke

    await injected(ctx)

  File "/opt/venv/lib/python3.12/site-packages/discord/commands/core.py", line 146, in wrapped

    raise ApplicationCommandInvokeError(exc) from exc

discord.errors.ApplicationCommandInvokeError: Application Command raised an exception: InteractionResponded: This interaction has already been responded to before